TERM environment variable not set.
06/25/23 13:46:24: Running /var/spool/slurm/slurmd/job2965286/slurm_script
13:46:24: Found 3 files in /projects/0/nwo2021025/iHESP_data/HighResMIP/HR/B.E.13.B1950TRC5.ne120_t12.cesm-ihesp-2051-2100.014
CDO executable: /home/jasperdj/.conda/envs/geo/bin/cdo
/projects/0/nwo2021025/iHESP_data/HighResMIP/HR/B.E.13.B1950TRC5.ne120_t12.cesm-ihesp-2051-2100.014/atm/proc/tseries/hour_6A/B.E.13.B1950TRC5.ne120_t12.cesm-ihesp-2051-2100.014.cam.h3.U.2070010100-2071010100.nc /projects/0/nwo2021025/iHESP_data/HighResMIP/HR/B.E.13.B1950TRC5.ne120_t12.cesm-ihesp-2051-2100.014/atm/proc/tseries/hour_6A/B.E.13.B1950TRC5.ne120_t12.cesm-ihesp-2051-2100.014.cam.h3.V.2070010100-2071010100.nc /projects/0/nwo2021025/iHESP_data/HighResMIP/HR/B.E.13.B1950TRC5.ne120_t12.cesm-ihesp-2051-2100.014/atm/proc/tseries/hour_6A/B.E.13.B1950TRC5.ne120_t12.cesm-ihesp-2051-2100.014.cam.h4.PS.207001-207012.nc
/home/jasperdj/.conda/envs/geo/lib/python3.9/site-packages/_distutils_hack/__init__.py:33: UserWarning: Setuptools is replacing distutils.
  warnings.warn("Setuptools is replacing distutils.")
25-06-2023 13:46:28 INFO: read path: /projects/0/nwo2021025/iHESP_data/HighResMIP/HR/B.E.13.B1950TRC5.ne120_t12.cesm-ihesp-2051-2100.014/atm/proc/tseries/hour_6A:
input file(s):
B.E.13.B1950TRC5.ne120_t12.cesm-ihesp-2051-2100.014.cam.h3.U.2070010100-2071010100.nc
B.E.13.B1950TRC5.ne120_t12.cesm-ihesp-2051-2100.014.cam.h3.V.2070010100-2071010100.nc
B.E.13.B1950TRC5.ne120_t12.cesm-ihesp-2051-2100.014.cam.h4.PS.207001-207012.nc
25-06-2023 13:46:28 INFO: opening with chunks argument: {'time': 1, 'ncol': 'auto', 'lev': -1}...
Python version: 3.9.13 | packaged by conda-forge | (main, May 27 2022, 16:56:21) 
[GCC 10.3.0]
Path: ['/gpfs/home2/jasperdj/sai-git/sai/jobs/windshear/snellius', '/home/jasperdj/.conda/envs/geo/lib/python39.zip', '/home/jasperdj/.conda/envs/geo/lib/python3.9', '/home/jasperdj/.conda/envs/geo/lib/python3.9/lib-dynload', '/home/jasperdj/.conda/envs/geo/lib/python3.9/site-packages']

INSTALLED VERSIONS
------------------
commit: None
python: 3.9.13 | packaged by conda-forge | (main, May 27 2022, 16:56:21) 
[GCC 10.3.0]
python-bits: 64
OS: Linux
OS-release: 4.18.0-477.13.1.el8_8.x86_64
machine: x86_64
processor: x86_64
byteorder: little
LC_ALL: None
LANG: None
LOCALE: ('en_US', 'UTF-8')
libhdf5: 1.12.2
libnetcdf: 4.8.1

xarray: 2022.11.0
pandas: 1.5.3
numpy: 1.24.3
scipy: 1.10.1
netCDF4: 1.6.2
pydap: None
h5netcdf: None
h5py: None
Nio: None
zarr: None
cftime: 1.6.2
nc_time_axis: 1.4.1
PseudoNetCDF: None
rasterio: None
cfgrib: None
iris: None
bottleneck: 1.3.5
dask: 2023.4.1
distributed: 2023.4.1
matplotlib: 3.7.1
cartopy: 0.21.1
seaborn: None
numbagg: None
fsspec: 2023.4.0
cupy: None
pint: None
sparse: None
flox: None
numpy_groupies: None
setuptools: 67.8.0
pip: 23.1.2
conda: None
pytest: None
IPython: 8.12.0
sphinx: None
Traceback (most recent call last):
  File "/home/jasperdj/.conda/envs/geo/lib/python3.9/site-packages/xarray/core/dataset.py", line 1339, in _construct_dataarray
    variable = self._variables[name]
KeyError: 'date_written'

During handling of the above exception, another exception occurred:

Traceback (most recent call last):
  File "/home/jasperdj/.conda/envs/geo/lib/python3.9/site-packages/xarray/core/concat.py", line 556, in _dataset_concat
    vars = ensure_common_dims([ds[name].variable for ds in datasets])
  File "/home/jasperdj/.conda/envs/geo/lib/python3.9/site-packages/xarray/core/concat.py", line 556, in <listcomp>
    vars = ensure_common_dims([ds[name].variable for ds in datasets])
  File "/home/jasperdj/.conda/envs/geo/lib/python3.9/site-packages/xarray/core/dataset.py", line 1430, in __getitem__
    return self._construct_dataarray(key)
  File "/home/jasperdj/.conda/envs/geo/lib/python3.9/site-packages/xarray/core/dataset.py", line 1341, in _construct_dataarray
    _, name, variable = _get_virtual_variable(self._variables, name, self.dims)
  File "/home/jasperdj/.conda/envs/geo/lib/python3.9/site-packages/xarray/core/dataset.py", line 177, in _get_virtual_variable
    raise KeyError(key)
KeyError: 'date_written'

During handling of the above exception, another exception occurred:

Traceback (most recent call last):
  File "/gpfs/home2/jasperdj/sai-git/sai/jobs/windshear/snellius/windshear.py", line 215, in <module>
    main()
  File "/gpfs/home2/jasperdj/sai-git/sai/jobs/windshear/snellius/windshear.py", line 128, in main
    with xr.open_mfdataset(args.files, chunks=CHUNKS, parallel=True, 
  File "/home/jasperdj/.conda/envs/geo/lib/python3.9/site-packages/xarray/backends/api.py", line 1011, in open_mfdataset
    combined = _nested_combine(
  File "/home/jasperdj/.conda/envs/geo/lib/python3.9/site-packages/xarray/core/combine.py", line 365, in _nested_combine
    combined = _combine_nd(
  File "/home/jasperdj/.conda/envs/geo/lib/python3.9/site-packages/xarray/core/combine.py", line 239, in _combine_nd
    combined_ids = _combine_all_along_first_dim(
  File "/home/jasperdj/.conda/envs/geo/lib/python3.9/site-packages/xarray/core/combine.py", line 275, in _combine_all_along_first_dim
    new_combined_ids[new_id] = _combine_1d(
  File "/home/jasperdj/.conda/envs/geo/lib/python3.9/site-packages/xarray/core/combine.py", line 298, in _combine_1d
    combined = concat(
  File "/home/jasperdj/.conda/envs/geo/lib/python3.9/site-packages/xarray/core/concat.py", line 243, in concat
    return _dataset_concat(
  File "/home/jasperdj/.conda/envs/geo/lib/python3.9/site-packages/xarray/core/concat.py", line 558, in _dataset_concat
    raise ValueError(f"{name!r} is not present in all datasets.")
ValueError: 'date_written' is not present in all datasets.

JOB STATISTICS
==============
Job ID: 2965286
Cluster: snellius
User/Group: jasperdj/jasperdj
State: RUNNING
Nodes: 1
Cores per node: 128
CPU Utilized: 00:00:00
CPU Efficiency: 0.00% of 00:38:24 core-walltime
Job Wall-clock time: 00:00:18
Memory Utilized: 0.00 MB (estimated maximum)
Memory Efficiency: 0.00% of 224.00 GB (1.75 GB/core)
WARNING: Efficiency statistics may be misleading for RUNNING jobs.
